Workbook

Sheet Reformulated IS
A1: Rheinmetall AG — Reformulated Income Statement
A2: € million | IFRS | Fiscal year ended 31 December | External / internal cost lens
A3: 2025 and 2024 use the 2025 Annual Report (2024 restated for IFRS 5); 2023 is as reported in the 2024 Annual Report and is not restated for the 2025 civilian-business discontinuation.
A5: REFORMULATED INCOME STATEMENT
A6: Line item | B6: 2025 (€m) | C6: 2024 Restated (€m) | D6: 2023 As reported (€m) | E6: Status | F6: Primary source | G6: Calculation / classification | H6: Notes
A7: Sales | B7: =B62 -> 9935 | C7: =C62 -> 7715 | D7: =D62 -> 7176 | E7: CHECK / AGENT | F7: Reported inputs below | G7: Linked to reported Sales
A8: Changes in inventories and own work capitalised | B8: =B63 -> 521 | C8: =C63 -> 132 | D8: =D63 -> 696 | E8: CHECK / AGENT | F8: Reported inputs below | G8: Linked to reported inventory change + own work capitalised
A9: Value of Production | B9: =SUM(B7:B8) -> 10456 | C9: =SUM(C7:C8) -> 7847 | D9: =SUM(D7:D8) -> 7872 | E9: AGENT | F9: Calculation | G9: Sales + changes in inventories / own work
A10: Cost of materials | B10: =B65 -> -5252 | C10: =C65 -> -3693 | D10: =D65 -> -3935 | E10: CHECK / AGENT | F10: Reported inputs below | G10: Reported operating cost
A11: Other operating expenses (recurring) | B11: =B68-B45-B48 -> -1103 | C11: =C68-C45-C48 -> -864 | D11: =D68-D45-D48 -> -881 | E11: AGENT | F11: Notes 15 / acquisition note | G11: Reported Opex less disclosed unusual disposal losses and M&A costs
A12: Other operating income (recurring) | B12: =B64-SUM(B42:B44)-B47 -> 110 | C12: =C64-SUM(C42:C44)-C47 -> 98 | D12: =D64-SUM(D42:D44)-D47 -> 93 | E12: AGENT | F12: Note 11 | G12: Reported OI less refunds, provision reversals, disposal gains and asset reversals
A13: Added Value | B13: =SUM(B9:B12) -> 4211 | C13: =SUM(C9:C12) -> 3388 | D13: =SUM(D9:D12) -> 3149 | E13: AGENT | F13: Calculation | G13: Value of Production + materials + recurring Opex + recurring OI
A14: Personnel expenses | B14: =B66 -> -2314 | C14: =C66 -> -1844 | D14: =D66 -> -2047 | E14: CHECK / AGENT | F14: Reported inputs below | G14: Reported personnel expense
A15: EBITDA | B15: =SUM(B13:B14) -> 1897 | C15: =SUM(C13:C14) -> 1544 | D15: =SUM(D13:D14) -> 1102 | E15: AGENT | F15: Calculation | G15: Added Value + personnel expense
A16: Amortization & depreciation (excl. impairment) | B16: =B67-B46 -> -389 | C16: =C67-C46 -> -284 | D16: =D67-D46 -> -302 | E16: AGENT | F16: Note 14 | G16: Reported D&A / impairment less impairment
A17: Restructuring costs removed | B17: =-B53 -> 7 | C17: =-C53 -> 2 | D17: =-D53 -> 1 | E17: AGENT | F17: CMR special-item reconciliation | G17: Add-back because original expense line is not disclosed
A18: Core Operating Income | B18: =SUM(B15:B17) -> 1515 | C18: =SUM(C15:C17) -> 1262 | D18: =SUM(D15:D17) -> 801 | E18: AGENT | F18: Calculation | G18: EBITDA + recurring D&A + restructuring add-back
A19: Result from equity-method investments (recurring) | B19: =B69-B49-B51-B52 -> 1 | C19: =C69-C49-C51-C52 -> -33 | D19: =D69-D49-D51-D52 -> 4 | E19: AGENT | F19: Note 22 | G19: Reported at-equity result less disclosed disposal / remeasurement gains
A20: Other financial result (recurring, non-interest) | B20: =B70-B50 -> -22 | C20: =C70-C50 -> -9 | D20: =D70-D50 -> -6 | E20: AGENT | F20: Note 7 / reported financial result | G20: Reported other financial result less blackned step-up gain
A21: Non-core Operating Income | B21: =SUM(B19:B20) -> -21 | C21: =SUM(C19:C20) -> -42 | D21: =SUM(D19:D20) -> -2 | E21: AGENT | F21: Calculation | G21: Recurring at-equity result + recurring other financial result
A22: Operating Income | B22: =B18+B21 -> 1494 | C22: =C18+C21 -> 1220 | D22: =D18+D21 -> 799 | E22: AGENT | F22: Calculation | G22: Core + non-core operating income
A23: Interest income | B23: =B71 -> 4 | C23: =C71 -> 14 | D23: =D71 -> 29 | E23: CHECK / AGENT | F23: Reported inputs below | G23: Interest income
A24: Interest expense | B24: =B72 -> -116 | C24: =C72 -> -116 | D24: =D72 -> -111 | E24: CHECK / AGENT | F24: Reported inputs below | G24: Interest expense
A25: Net financial result | B25: =SUM(B23:B24) -> -112 | C25: =SUM(C23:C24) -> -102 | D25: =SUM(D23:D24) -> -82 | E25: AGENT | F25: Calculation | G25: Interest income + interest expense
A26: Income before unusual items and taxes | B26: =B22+B25 -> 1382 | C26: =C22+C25 -> 1118 | D26: =D22+D25 -> 717 | E26: AGENT | F26: Calculation | G26: Operating Income + net financial result
A27: Unusual items | B27: =B58 -> -136 | C27: =C58 -> 271 | D27: =D58 -> 51 | E27: AGENT | F27: Unusual-item schedule | G27: Linked to total unusual items
A28: Income before taxes (comprehensive-income bridge subtotal) | B28: =SUM(B26:B27) -> 1246 | C28: =SUM(C26:C27) -> 1389 | D28: =SUM(D26:D27) -> 768 | E28: AGENT | F28: Calculation | G28: Income before unusual items and taxes + unusual items | H28: Includes tax-only and OCI unusual items per the reformulation method.
A29: Income taxes — recurring continuing operations | B29: =-B73-B54-B55 -> -395 | C29: =-C73-C54-C55 -> -327 | D29: =-D73-D54-D55 -> -188 | E29: AGENT | F29: Tax notes | G29: − reported continuing tax expense − signed prior-period tax effect − signed rate-change effect
A30: Income taxes — discontinued operations | B30: =B74 -> -27 | C30: =C74 -> -14 | D30: =D74 -> 15 | E30: AGENT | F30: Discontinued-operations notes | G30: Signed tax effect from discontinued operations
A31: Tax on OCI | B31: =B75 -> -38 | C31: =C75 -> -47 | D31: =D75 -> 2 | E31: AGENT | F31: OCI tax note | G31: Signed tax on OCI
A32: Total income taxes | B32: =SUM(B29:B31) -> -460 | C32: =SUM(C29:C31) -> -388 | D32: =SUM(D29:D31) -> -171 | E32: AGENT | F32: Calculation | G32: Sum of recurring continuing tax + discontinued tax + OCI tax
A33: Rounding / reconciliation | B33: =B76-(B28+B32) -> 0 | C33: =C76-(C28+C32) -> -2 | D33: =D76-(D28+D32) -> 0 | E33: AGENT | F33: Calculation | G33: Reported comprehensive income less bridge subtotal and total tax | H33: Source / note rounding residual.
A34: Total comprehensive income | B34: =B28+B32+B33 -> 786 | C34: =C28+C32+C33 -> 999 | D34: =D28+D32+D33 -> 597 | E34: AGENT | F34: Calculation / reported check | G34: Bridge subtotal + total tax + rounding
A35: of which: non-controlling interests | B35: =B77 -> 150 | C35: =C77 -> 98 | D35: =D77 -> 39 | E35: CHECK / AGENT | F35: Reported comprehensive income | G35: Reported NCI split
A36: of which: Rheinmetall AG shareholders | B36: =B78 -> 636 | C36: =C78 -> 901 | D36: =D78 -> 558 | E36: CHECK / AGENT | F36: Reported comprehensive income | G36: Reported parent split
A40: UNUSUAL ITEMS SUPPORTING SCHEDULE
A41: Item | B41: 2025 (€m) | C41: 2024 Restated (€m) | D41: 2023 As reported (€m) | E41: Type | F41: Original line | G41: Criterion | H41: Primary source
A42: Refunds / insurance recoveries | B42: 118 | C42: 21 | D42: 5 | E42: Pre-tax | F42: Other operating income | G42: (a) refunds / insurance recoveries | H42: AR 2025 Note 11 p.219; AR 2024 Note 11 p.206
A43: Reversal of provisions | B43: 44 | C43: 55 | D43: 53 | E43: Pre-tax | F43: Other operating income | G43: (b) reversal of provisions | H43: AR 2025 Note 11 p.219; AR 2024 Note 11 p.206
A44: Disposal gains — fixed assets / divestments | B44: 1 | C44: 2 | D44: 0 | E44: Pre-tax | F44: Other operating income | G44: (c) disposal gains | H44: AR 2025 Note 11 p.219; AR 2024 Note 11 p.206
...

Sheet Managerial BS
A1: Rheinmetall AG — Managerial Balance Sheet
A2: € million | IFRS | Closing balances at 31 December | Consolidated incl. NCI
A3: 2025 and 2024 source balances are from the 2025 Annual Report; 2023 is from the 2024 Annual Report. The 2024 balance sheet is not restated for the 2025 IFRS 5 civilian-business discontinuation, so it is not fully scope-matched to the 2024 restated continuing-operations income statement. No unsupported 2024 disposal-group balance-sheet estimate is made.
A5: MANAGERIAL BALANCE SHEET
A6: Category | B6: 2025 (€m) | C6: 2024 (€m) | D6: 2023 (€m) | E6: Status | F6: Source / calculation | G6: Classification
A7: CURRENT OPERATING ASSETS
A8: Inventories | B8: 4721 | C8: 3989 | D8: 3244 | E8: 2025/24 CHECK; 2023 AGENT | F8: AR 2025 p.200 / Note 23 p.229; AR 2024 p.189 / Note 23 p.217 | G8: Operating; inventories include prepayments made.
A9: Contract assets | B9: 957 | C9: 692 | D9: 516 | E9: 2025/24 CHECK; 2023 AGENT | F9: AR 2025 p.200; AR 2024 p.189 | G9: Operating contract asset.
A10: Trade receivables | B10: 1907 | C10: 1959 | D10: 2021 | E10: 2025/24 CHECK; 2023 AGENT | F10: AR 2025 p.200; AR 2024 p.189 | G10: Operating receivable.
A11: Contract acquisition costs | B11: 122 | C11: 139 | D11: 93 | E11: AGENT | F11: AR 2025 Note 24 p.230; AR 2024 Note 24 p.217 | G11: Operating non-financial asset; included irrespective of IAS 1 maturity.
A12: Contract costs | B12: 76 | C12: 44 | D12: 41 | E12: AGENT | F12: AR 2025 Note 24 p.230; AR 2024 Note 24 p.217 | G12: Operating non-financial asset; included irrespective of IAS 1 maturity.
A13: Prepaid expenses | B13: 78 | C13: 80 | D13: 67 | E13: AGENT | F13: AR 2025 Note 24 p.230; AR 2024 Note 24 p.217 | G13: Operating non-financial asset.
A14: Other non-financial operating assets | B14: 59 | C14: 80 | D14: 60 | E14: AGENT | F14: AR 2025 Note 24 p.230; AR 2024 Note 24 p.217 | G14: Excludes other-tax receivables and pension surplus; 2024/23 combines subsidy, insurance and other non-financial rows.
A15: Derivative assets — operating-risk hedges | B15: 80 | C15: 41 | D15: 25 | E15: 2025/24 CHECK; 2023 AGENT | F15: AR 2025 Note 24 p.230 & Note 34 pp.248–249; AR 2024 Note 24 p.217 / Note 34 p.233 | G15: Operating; all maturities. Derivatives are disclosed as currency/commodity hedges.
A16: Current operating assets | B16: =SUM(B8:B15) -> 8000 | C16: =SUM(C8:C15) -> 7024 | D16: =SUM(D8:D15) -> 6067 | E16: CHECK / AGENT | F16: Sum of operating-asset lines above | G16: Managerial current operating assets.
A18: OPERATING LIABILITIES
A19: Contract liabilities | B19: 5642 | C19: 3866 | D19: 2594 | E19: 2025/24 CHECK; 2023 AGENT | F19: AR 2025 p.200; AR 2024 p.189 | G19: Operating liability.
A20: Trade liabilities | B20: 1186 | C20: 1151 | D20: 1222 | E20: 2025/24 CHECK; 2023 AGENT | F20: AR 2025 p.200; AR 2024 p.189 | G20: Operating liability.
A21: Other current provisions | B21: 891 | C21: 807 | D21: 690 | E21: 2025/24 CHECK; 2023 AGENT | F21: AR 2025 p.200 / Note 28 p.240; AR 2024 p.189 / Note 28 p.226 | G21: Operating provisions.
A22: Pension provisions | B22: 278 | C22: 527 | D22: 562 | E22: AGENT | F22: AR 2025 p.200; AR 2024 p.189 | G22: Operating pension obligation before plan surplus.
A23: Less: net defined-benefit asset / plan surplus | B23: -289 | C23: -275 | D23: -99 | E23: AGENT | F23: AR 2025 Note 24 p.230; AR 2024 Note 24 p.217 | G23: Netted against pension provisions under the method.
A24: Pension provisions, net of plan surplus | B24: =B22+B23 -> -11 | C24: =C22+C23 -> 252 | D24: =D22+D23 -> 463 | E24: CHECK / AGENT | F24: Pension provisions less plan surplus | G24: Operating liability; may be negative when plan surplus exceeds provision.
A25: Other non-current provisions | B25: 280 | C25: 285 | D25: 230 | E25: 2025/24 CHECK; 2023 AGENT | F25: AR 2025 p.200 / Note 28 p.240; AR 2024 p.189 / Note 28 p.226 | G25: Operating provisions regardless of maturity.
A26: Social-security liabilities | B26: 11 | C26: 14 | D26: 14 | E26: AGENT | F26: AR 2025 Note 30 p.243; AR 2024 Note 30 p.230 | G26: Operating non-financial liability.
A27: Other non-financial liabilities | B27: 89 | C27: 130 | D27: 77 | E27: AGENT | F27: AR 2025 Note 30 p.243; AR 2024 Note 30 p.230 | G27: Operating non-financial liability; excludes other-tax liabilities.
A28: Derivative liabilities — operating-risk hedges | B28: 20 | C28: 22 | D28: 24 | E28: 2025/24 CHECK; 2023 AGENT | F28: AR 2025 Note 30 p.243 & Note 34 pp.248–249; AR 2024 Note 30 p.230 / Note 34 p.233 | G28: Operating; all maturities. Currency/commodity hedges.
A29: Operating liabilities | B29: =SUM(B19:B21)+B24+SUM(B25:B28) -> 8108 | C29: =SUM(C19:C21)+C24+SUM(C25:C28) -> 6527 | D29: =SUM(D19:D21)+D24+SUM(D25:D28) -> 5314 | E29: CHECK / AGENT | F29: Contract/trade/provisions/pensions/non-financial liabilities/operating derivatives | G29: Recurring operating liabilities.
A30: Net operating working capital (NOWC) | B30: =B16-B29 -> -108 | C30: =C16-C29 -> 497 | D30: =D16-D29 -> 753 | E30: CHECK / AGENT | F30: Current operating assets − operating liabilities | G30: Closing-balance NOWC.
A32: NON-CURRENT OPERATING ASSETS
A33: Goodwill | B33: 1354 | C33: 1426 | D33: 1125 | E33: 2025/24 CHECK; 2023 AGENT | F33: AR 2025 p.200; AR 2024 p.189 | G33: Non-current operating asset.
A34: Other intangible assets | B34: 1244 | C34: 1376 | D34: 952 | E34: 2025/24 CHECK; 2023 AGENT | F34: AR 2025 p.200; AR 2024 p.189 | G34: Non-current operating asset.
A35: Right-of-use assets | B35: 338 | C35: 334 | D35: 271 | E35: 2025/24 CHECK; 2023 AGENT | F35: AR 2025 p.200; AR 2024 p.189 | G35: Non-current operating asset.
A36: Property, plant and equipment | B36: 1962 | C36: 1853 | D36: 1370 | E36: 2025/24 CHECK; 2023 AGENT | F36: AR 2025 p.200; AR 2024 p.189 | G36: Non-current operating asset.
A37: Investment property | B37: 2 | C37: 20 | D37: 22 | E37: 2025/24 CHECK; 2023 AGENT | F37: AR 2025 p.200; AR 2024 p.189 | G37: Operating by default under supplied methodology.
A38: Non-current operating assets | B38: =SUM(B33:B37) -> 4900 | C38: =SUM(C33:C37) -> 5009 | D38: =SUM(D33:D37) -> 3740 | E38: CHECK / AGENT | F38: Sum of non-current operating assets | G38: Managerial non-current operating assets.
A39: Gross operating invested capital | B39: =B16+B38 -> 12900 | C39: =C16+C38 -> 12033 | D39: =D16+D38 -> 9807 | E39: CHECK / AGENT | F39: Current operating assets + non-current operating assets | G39: Gross means before operating liabilities, not before depreciation.
A40: Net operating invested capital | B40: =B39-B29 -> 4792 | C40: =C39-C29 -> 5506 | D40: =D39-D29 -> 4493 | E40: CHECK / AGENT | F40: Gross operating invested capital − operating liabilities | G40: Operating capital net of recurring operating liabilities.
A42: NON-OPERATING ASSETS
A43: Investments accounted for using the equity method | B43: 213 | C43: 346 | D43: 373 | E43: 2025/24 CHECK; 2023 AGENT | F43: AR 2025 p.200; AR 2024 p.189 | G43: Non-operating asset; associated income is non-core operating income.
A44: Assets held for sale, net of associated liabilities | B44: =B71-B72 -> 562 | C44: =C71-C72 -> 0 | D44: =D71-D72 -> 35 | E44: CHECK / AGENT | F44: 2025: 1,270 − 708; 2024: none; 2023: 196 − 161. AR 2024 Note 8 p.204 detailed disposal-group net assets show €34m vs €35m from face totals due standalone rounding; face totals are used for the managerial identity. | G44: Non-operating net disposal-group asset; cash inside disposal group remains there.
...

Sheet ROE
A1: Rheinmetall AG — ROE Analysis
A2: € million | IFRS | Fiscal year ended 31 December | Consolidated incl. NCI | Closing equity
A3: 2025 and 2024 income-statement figures use the 2025 Annual Report (2024 restated for IFRS 5); 2023 is as reported in the 2024 Annual Report. The 2024 managerial balance sheet is not restated for the 2025 civilian-business discontinuation, so return decompositions using 2024 closing balance-sheet amounts retain that scope mismatch.
A5: ROE SUMMARY
A6: Measure / input | B6: 2025 | C6: 2024 Restated | D6: 2023 As reported | E6: Status | F6: Source / calculation | G6: Notes
A7: ROE on net income — direct | B7: ='Reformulated IS'!B80/'Managerial BS'!B65 -> 0.1487353 | C7: ='Reformulated IS'!C80/'Managerial BS'!C65 -> 0.18096305 | D7: ='Reformulated IS'!D80/'Managerial BS'!D65 -> 0.16085644 | E7: AGENT | F7: Reported net income / closing equity | G7: DuPont direct check.
A8: ROE on comprehensive income — direct | B8: ='Reformulated IS'!B34/'Managerial BS'!B65 -> 0.14000713 | C8: ='Reformulated IS'!C34/'Managerial BS'!C65 -> 0.2237402 | D8: ='Reformulated IS'!D34/'Managerial BS'!D65 -> 0.16387593 | E8: AGENT | F8: Reformulated IS total comprehensive income / closing equity | G8: Consolidated incl. NCI.
A9: OCI / equity bridge | B9: =('Reformulated IS'!B34-'Reformulated IS'!B80)/'Managerial BS'!B65 -> -0.0087281796 | C9: =('Reformulated IS'!C34-'Reformulated IS'!C80)/'Managerial BS'!C65 -> 0.042777156 | D9: =('Reformulated IS'!D34-'Reformulated IS'!D80)/'Managerial BS'!D65 -> 0.0030194894 | E9: AGENT | F9: (Comprehensive income − net income) / closing equity | G9: Dirty-surplus bridge.
A10: Bridge check | B10: =B8-B7-B9 -> 0 | C10: =C8-C7-C9 -> 0 | D10: =D8-D7-D9 -> -7.3725748e-18 | E10: AGENT | F10: ROE(CI) − ROE(NI) − OCI/equity | G10: Should be zero.
A12: DUPONT — REPORTED FIGURES
A13: Measure / input | B13: 2025 | C13: 2024 Restated | D13: 2023 As reported | E13: Status | F13: Source / calculation | G13: Notes
A14: Net income | B14: ='Reformulated IS'!B80 -> 835 | C14: ='Reformulated IS'!C80 -> 808 | D14: ='Reformulated IS'!D80 -> 586 | E14: CHECK | F14: Reformulated IS reported-source input | G14: Reported figure.
A15: Continuing net income | B15: =B125 -> 1176 | C15: =C125 -> 840 | D15: =D125 -> 630 | E15: AGENT | F15: ROE support input; AR 2025 p.199; AR 2024 p.188 | G15: Reported continuing operations.
A16: Earnings before taxes (EBT) | B16: ='Reformulated IS'!B79 -> 1572 | C16: ='Reformulated IS'!C79 -> 1168 | D16: ='Reformulated IS'!D79 -> 815 | E16: CHECK | F16: Reformulated IS reported-source input | G16: Reported continuing EBT.
A17: EBIT | B17: =B124 -> 1684 | C17: =C124 -> 1270 | D17: =D124 -> 897 | E17: AGENT | F17: ROE support input; AR 2025 p.199; AR 2024 p.188 | G17: Reported EBIT.
A18: Sales | B18: ='Reformulated IS'!B7 -> 9935 | C18: ='Reformulated IS'!C7 -> 7715 | D18: ='Reformulated IS'!D7 -> 7176 | E18: CHECK | F18: Reformulated IS | G18: Reported sales.
A19: Total assets | B19: ='Managerial BS'!B70 -> 16772 | C19: ='Managerial BS'!C70 -> 14344 | D19: ='Managerial BS'!D70 -> 11707 | E19: CHECK | F19: Managerial BS — reported total assets | G19: Closing balance.
A20: Equity incl. NCI | B20: ='Managerial BS'!B65 -> 5614 | C20: ='Managerial BS'!C65 -> 4465 | D20: ='Managerial BS'!D65 -> 3643 | E20: CHECK | F20: Managerial BS — equity incl. NCI | G20: Closing balance.
A21: Tax effect = continuing net income / EBT | B21: =B15/B16 -> 0.7480916 | C21: =C15/C16 -> 0.71917808 | D21: =D15/D16 -> 0.77300613 | E21: AGENT | F21: Continuing net income / EBT | G21: Tax effect in DuPont split.
A22: Discontinued effect = net income / continuing net income | B22: =B14/B15 -> 0.71003401 | C22: =C14/C15 -> 0.96190476 | D22: =D14/D15 -> 0.93015873 | E22: AGENT | F22: Net income / continuing net income | G22: Discontinued-operations effect.
A23: Net income / EBT | B23: =B14/B16 -> 0.53117048 | C23: =C14/C16 -> 0.69178082 | D23: =D14/D16 -> 0.7190184 | E23: AGENT | F23: Net income / EBT | G23: Should equal tax effect × discontinued effect.
A24: Tax × discontinued split check | B24: =B21*B22-B23 -> 0 | C24: =C21*C22-C23 -> 0 | D24: =D21*D22-D23 -> 0 | E24: AGENT | F24: Tax effect × discontinued effect − net income/EBT | G24: Should be zero.
A25: EBT / EBIT | B25: =B16/B17 -> 0.93349169 | C25: =C16/C17 -> 0.91968504 | D25: =D16/D17 -> 0.90858417 | E25: AGENT | F25: EBT / EBIT | G25: Reported DuPont.
A26: EBIT / sales | B26: =B17/B18 -> 0.16950176 | C26: =C17/C18 -> 0.16461439 | D26: =D17/D18 -> 0.125 | E26: AGENT | F26: EBIT / sales | G26: Reported DuPont.
A27: Sales / total assets | B27: =B18/B19 -> 0.59235631 | C27: =C18/C19 -> 0.53785555 | D27: =D18/D19 -> 0.6129666 | E27: AGENT | F27: Sales / total assets | G27: Closing-balance turnover.
A28: Total assets / equity | B28: =B19/B20 -> 2.9875312 | C28: =C19/C20 -> 3.212542 | D28: =D19/D20 -> 3.2135603 | E28: AGENT | F28: Total assets / equity | G28: Closing-balance leverage.
A29: DuPont ROE | B29: =B23*B25*B26*B27*B28 -> 0.1487353 | C29: =C23*C25*C26*C27*C28 -> 0.18096305 | D29: =D23*D25*D26*D27*D28 -> 0.16085644 | E29: AGENT | F29: Product of DuPont factors | G29: Reported DuPont ROE.
A30: Direct ROE on net income | B30: =B14/B20 -> 0.1487353 | C30: =C14/C20 -> 0.18096305 | D30: =D14/D20 -> 0.16085644 | E30: AGENT | F30: Net income / equity | G30: Direct check.
A31: Decomposition check | B31: =B29-B30 -> 0 | C31: =C29-C30 -> 0 | D31: =D29-D30 -> 0 | E31: AGENT | F31: DuPont ROE − direct ROE | G31: Technical tolerance 0.01 pp.
A33: DUPONT LIMITATIONS — QUANTIFIED
A34: Measure / input | B34: 2025 | C34: 2024 Restated | D34: 2023 As reported | E34: Status | F34: Source / calculation | G34: Notes
A35: 1. Core return on sales | B35: ='Reformulated IS'!B18/'Reformulated IS'!B7 -> 0.15249119 | C35: ='Reformulated IS'!C18/'Reformulated IS'!C7 -> 0.16357745 | D35: ='Reformulated IS'!D18/'Reformulated IS'!D7 -> 0.11162207 | E35: AGENT | F35: Reformulated IS core operating income / sales | G35: Limitation 1.
A36: 1. Reported EBIT / sales | B36: =B17/B18 -> 0.16950176 | C36: =C17/C18 -> 0.16461439 | D36: =D17/D18 -> 0.125 | E36: AGENT | F36: Reported EBIT / sales | G36: Limitation 1.
A37: 1. Margin-definition difference | B37: =B35-B36 -> -0.017010569 | C37: =C35-C36 -> -0.001036941 | D37: =D35-D36 -> -0.013377926 | E37: AGENT | F37: Core ROS − reported EBIT margin | G37: Quantifies margin-definition difference.
A38: 2. Operating turnover = sales / gross operating invested capital | B38: ='Reformulated IS'!B7/'Managerial BS'!B39 -> 0.77015504 | C38: ='Reformulated IS'!C7/'Managerial BS'!C39 -> 0.64115349 | D38: ='Reformulated IS'!D7/'Managerial BS'!D39 -> 0.73172224 | E38: AGENT | F38: Sales / managerial gross operating invested capital | G38: Limitation 2.
A39: 2. Total-asset turnover | B39: ='Reformulated IS'!B7/'Managerial BS'!B70 -> 0.59235631 | C39: ='Reformulated IS'!C7/'Managerial BS'!C70 -> 0.53785555 | D39: ='Reformulated IS'!D7/'Managerial BS'!D70 -> 0.6129666 | E39: AGENT | F39: Sales / reported total assets | G39: Limitation 2.
A40: 2. Turnover-definition difference | B40: =B38-B39 -> 0.17779873 | C40: =C38-C39 -> 0.10329795 | D40: =D38-D39 -> 0.11875564 | E40: AGENT | F40: Operating turnover − total-asset turnover | G40: Quantifies denominator effect.
A41: 3. Operating liabilities / equity | B41: ='Managerial BS'!B29/'Managerial BS'!B65 -> 1.4442465 | C41: ='Managerial BS'!C29/'Managerial BS'!C65 -> 1.4618141 | D41: ='Managerial BS'!D29/'Managerial BS'!D65 -> 1.4586879 | E41: AGENT | F41: Managerial operating liabilities / equity | G41: Limitation 3.
A42: 3. Financial debt + other financing liabilities / equity | B42: =('Managerial BS'!B51+'Managerial BS'!B52)/'Managerial BS'!B65 -> 0.23227645 | C42: =('Managerial BS'!C51+'Managerial BS'!C52)/'Managerial BS'!C65 -> 0.55991041 | D42: =('Managerial BS'!D51+'Managerial BS'!D52)/'Managerial BS'!D65 -> 0.55174307 | E42: AGENT | F42: Managerial financial debt + other financing liabilities / equity | G42: Limitation 3.
A43: 3. Total assets / equity | B43: ='Managerial BS'!B70/'Managerial BS'!B65 -> 2.9875312 | C43: ='Managerial BS'!C70/'Managerial BS'!C65 -> 3.212542 | D43: ='Managerial BS'!D70/'Managerial BS'!D65 -> 3.2135603 | E43: AGENT | F43: Reported total assets / equity | G43: Reported leverage context.
...

Sheet ROI
A1: Rheinmetall AG — ROI Analysis
A2: € million | IFRS | Fiscal year ended 31 December | Consolidated incl. NCI | Closing invested-capital balances
A3: ROI is calculated only from the current Reformulated IS and Managerial BS sheets, as required. 2025/2024 income-statement figures use the 2025 Annual Report (2024 restated for IFRS 5); 2023 is as reported in the 2024 Annual Report. The 2024 managerial balance sheet is not restated for the 2025 civilian-business discontinuation, so 2024 return measures retain that scope mismatch.
A5: ROI COMPARISON TO TEAM WORKBOOK
A6: Measure | B6: Year | C6: Workbook | D6: Agent | E6: Difference (pp) | F6: Status | G6: Source / calculation
A7: Gross ROI | B7: 2025 | C7: 0.10911079 | D7: =B28 -> 0.10889213 | E7: =IF(C7="","",(D7-C7)*100) -> -0.021865889 | F7: =IF(C7="","AGENT",IF(ABS(D7-C7)<=0.0001,"MATCH","WORKBOOK DEFECT")) -> WORKBOOK DEFECT | G7: Team workbook ROI + Decomposition vs current step-by-step workbook. 2025 difference traces to the current Reformulated IS omitting the disclosed €3m NVL acquisition transaction cost add-back; source IS is not changed in this ROI step.
A8: Gross ROI | B8: 2024 | C8: 0.097431782 | D8: =C28 -> 0.097913323 | E8: =IF(C8="","",(D8-C8)*100) -> 0.048154093 | F8: =IF(C8="","AGENT",IF(ABS(D8-C8)<=0.0001,"MATCH","WORKBOOK DEFECT")) -> WORKBOOK DEFECT | G8: Team workbook ROI + Decomposition vs current step-by-step workbook. 2024 team ROI uses operating income €6m below the current Reformulated IS, consistent with not removing the €6m Loc Performance acquisition transaction cost.
A9: Gross ROI | B9: 2023 | D9: =D28 -> 0.077867654 | E9: =IF(C9="","",(D9-C9)*100) | F9: =IF(C9="","AGENT",IF(ABS(D9-C9)<=0.0001,"MATCH","METHOD DIFFERENCE")) -> AGENT | G9: No 2023 ROI result is present in the supplied team workbook; Agent result only.
A10: Net ROI | B10: 2025 | C10: 0.26674982 | D10: =B48 -> 0.26621525 | E10: =IF(C10="","",(D10-C10)*100) -> -0.053456878 | F10: =IF(C10="","AGENT",IF(ABS(D10-C10)<=0.0001,"MATCH","WORKBOOK DEFECT")) -> WORKBOOK DEFECT | G10: Same 2025 operating-income difference as Gross ROI; denominators are from the current Managerial BS.
A11: Net ROI | B11: 2024 | C11: 0.20461824 | D11: =C48 -> 0.20562953 | E11: =IF(C11="","",(D11-C11)*100) -> 0.10112928 | F11: =IF(C11="","AGENT",IF(ABS(D11-C11)<=0.0001,"MATCH","WORKBOOK DEFECT")) -> WORKBOOK DEFECT | G11: Same 2024 operating-income difference as Gross ROI; denominators are from the current Managerial BS.
A12: Net ROI | B12: 2023 | D12: =D48 -> 0.16151203 | E12: =IF(C12="","",(D12-C12)*100) | F12: =IF(C12="","AGENT",IF(ABS(D12-C12)<=0.0001,"MATCH","METHOD DIFFERENCE")) -> AGENT | G12: No 2023 ROI result is present in the supplied team workbook; Agent result only.
A14: GROSS ROI DECOMPOSITION
A15: Measure / input | B15: 2025 | C15: 2024 Restated | D15: 2023 As reported | E15: Status | F15: Source / calculation | G15: Notes
A16: Core operating income | B16: ='Reformulated IS'!B18 -> 1515 | C16: ='Reformulated IS'!C18 -> 1262 | D16: ='Reformulated IS'!D18 -> 801 | E16: CHECK | F16: Reformulated IS — Core Operating Income | G16: Recurring core operating numerator.
A17: Gross operating invested capital | B17: ='Managerial BS'!B39 -> 12900 | C17: ='Managerial BS'!C39 -> 12033 | D17: ='Managerial BS'!D39 -> 9807 | E17: CHECK | F17: Managerial BS — Gross operating invested capital | G17: Closing balance; gross means before operating liabilities.
A18: Core return on gross operating invested capital | B18: =B16/B17 -> 0.11744186 | C18: =C16/C17 -> 0.10487825 | D18: =D16/D17 -> 0.081676354 | E18: AGENT | F18: Core operating income / gross operating invested capital | G18: Core gross return.
A19: Core capital weight | B19: =B17/B27 -> 0.94023324 | C19: =C17/C27 -> 0.96573034 | D19: =D17/D27 -> 0.9557548 | E19: AGENT | F19: Gross operating invested capital / total gross invested capital | G19: Core share of total gross invested capital.
A20: Core contribution to Gross ROI | B20: =B18*B19 -> 0.11042274 | C20: =C18*C19 -> 0.10128411 | D20: =D18*D19 -> 0.078062567 | E20: AGENT | F20: Core return × core capital weight | G20: Weighted core contribution.
A21: Non-core operating income | B21: ='Reformulated IS'!B21 -> -21 | C21: ='Reformulated IS'!C21 -> -42 | D21: ='Reformulated IS'!D21 -> -2 | E21: CHECK | F21: Reformulated IS — Non-core Operating Income | G21: Recurring non-core operating numerator.
A22: Non-operating assets | B22: ='Managerial BS'!B46 -> 820 | C22: ='Managerial BS'!C46 -> 427 | D22: ='Managerial BS'!D46 -> 454 | E22: CHECK | F22: Managerial BS — Non-operating assets | G22: Closing non-operating asset pool.
A23: Non-core return on non-operating assets | B23: =IF(B22=0,"",B21/B22) -> -0.025609756 | C23: =IF(C22=0,"",C21/C22) -> -0.098360656 | D23: =IF(D22=0,"",D21/D22) -> -0.0044052863 | E23: AGENT | F23: Non-core operating income / non-operating assets | G23: Return on non-operating assets.
A24: Non-core capital weight | B24: =B22/B27 -> 0.059766764 | C24: =C22/C27 -> 0.034269663 | D24: =D22/D27 -> 0.0442452 | E24: AGENT | F24: Non-operating assets / total gross invested capital | G24: Non-core share of total gross invested capital.
A25: Non-core contribution to Gross ROI | B25: =B23*B24 -> -0.0015306122 | C25: =C23*C24 -> -0.0033707865 | D25: =D23*D24 -> -0.00019491278 | E25: AGENT | F25: Non-core return × non-core capital weight | G25: Weighted non-core contribution.
A26: Operating income | B26: ='Reformulated IS'!B22 -> 1494 | C26: ='Reformulated IS'!C22 -> 1220 | D26: ='Reformulated IS'!D22 -> 799 | E26: CHECK | F26: Reformulated IS — Operating Income | G26: Core + non-core operating income.
A27: Total gross invested capital | B27: ='Managerial BS'!B47 -> 13720 | C27: ='Managerial BS'!C47 -> 12460 | D27: ='Managerial BS'!D47 -> 10261 | E27: CHECK | F27: Managerial BS — Total gross invested capital | G27: Gross operating invested capital + non-operating assets.
A28: Gross ROI — direct | B28: =B26/B27 -> 0.10889213 | C28: =C26/C27 -> 0.097913323 | D28: =D26/D27 -> 0.077867654 | E28: AGENT | F28: Operating income / total gross invested capital | G28: Principal Gross ROI.
A29: Gross ROI — decomposed | B29: =B20+B25 -> 0.10889213 | C29: =C20+C25 -> 0.097913323 | D29: =D20+D25 -> 0.077867654 | E29: AGENT | F29: Core contribution + non-core contribution | G29: Required weighted decomposition.
A30: Decomposition check | B30: =B29-B28 -> 0 | C30: =C29-C28 -> 0 | D30: =D29-D28 -> 0 | E30: AGENT | F30: Decomposed Gross ROI − direct Gross ROI | G30: Technical tolerance: 0.01 pp.
A31: Capital weights total | B31: =B19+B24 -> 1 | C31: =C19+C24 -> 1 | D31: =D19+D24 -> 1 | E31: AGENT | F31: Core capital weight + non-core capital weight | G31: Must equal 100%.
A32: Capital weights check | B32: =B31-1 -> 0 | C32: =C31-1 -> 0 | D32: =D31-1 -> 0 | E32: AGENT | F32: Capital weights total − 100% | G32: Technical tolerance: 0.01 pp.
A34: NET ROI DECOMPOSITION
A35: Measure / input | B35: 2025 | C35: 2024 Restated | D35: 2023 As reported | E35: Status | F35: Source / calculation | G35: Notes
A36: Core operating income | B36: ='Reformulated IS'!B18 -> 1515 | C36: ='Reformulated IS'!C18 -> 1262 | D36: ='Reformulated IS'!D18 -> 801 | E36: CHECK | F36: Reformulated IS — Core Operating Income | G36: Recurring core operating numerator.
A37: Net operating invested capital | B37: ='Managerial BS'!B40 -> 4792 | C37: ='Managerial BS'!C40 -> 5506 | D37: ='Managerial BS'!D40 -> 4493 | E37: CHECK | F37: Managerial BS — Net operating invested capital | G37: Closing operating capital net of recurring operating liabilities.
A38: Core return on net operating invested capital | B38: =B36/B37 -> 0.31615192 | C38: =C36/C37 -> 0.2292045 | D38: =D36/D37 -> 0.17827732 | E38: AGENT | F38: Core operating income / net operating invested capital | G38: Core net return.
A39: Core capital weight | B39: =B37/B47 -> 0.85388453 | C39: =C37/C47 -> 0.92802966 | D39: =D37/D47 -> 0.90822721 | E39: AGENT | F39: Net operating invested capital / total net invested capital | G39: Core share of total net invested capital.
A40: Core contribution to Net ROI | B40: =B38*B39 -> 0.26995723 | C40: =C38*C39 -> 0.21270858 | D40: =D38*D39 -> 0.16191631 | E40: AGENT | F40: Core return × core capital weight | G40: Weighted core contribution.
A41: Non-core operating income | B41: ='Reformulated IS'!B21 -> -21 | C41: ='Reformulated IS'!C21 -> -42 | D41: ='Reformulated IS'!D21 -> -2 | E41: CHECK | F41: Reformulated IS — Non-core Operating Income | G41: Recurring non-core operating numerator.
A42: Non-operating assets | B42: ='Managerial BS'!B46 -> 820 | C42: ='Managerial BS'!C46 -> 427 | D42: ='Managerial BS'!D46 -> 454 | E42: CHECK | F42: Managerial BS — Non-operating assets | G42: Closing non-operating asset pool.
A43: Non-core return on non-operating assets | B43: =IF(B42=0,"",B41/B42) -> -0.025609756 | C43: =IF(C42=0,"",C41/C42) -> -0.098360656 | D43: =IF(D42=0,"",D41/D42) -> -0.0044052863 | E43: AGENT | F43: Non-core operating income / non-operating assets | G43: Return on non-operating assets.
...
