Workbook

Sheet Income Statement
A1: Rheinmetall AG (RHM-DE)
A2: €1010.60
A5: Rheinmetall AG Income Statement (Reported) | G5: Rheinmetall AG Reclassified Income Statement (External/Internal Costs)
A6: RHM-DE 5334588 Xetra Common stock | G6: RHM-DE 5334588 Xetra Common stock
B8: 31 DEC '25 | C8: 31 DEC '24 | H8: 31 DEC '25 | I8: 31 DEC '24
A10: Sales | B10: 9935 | C10: 7715 | G10: Sales | H10: =B10 -> 9935 | I10: =C10 -> 7715
A11: Changes in inventories and work performed by the enterprise and capitalised | B11: 521 | C11: 132 | G11: Changes in inventories and work performed by the enterprise and capitalised | H11: =B11 -> 521 | I11: =C11 -> 132
A12: Total revenue | B12: 10456 | C12: 7847 | G12: Value of Production | H12: =H10+H11 -> 10456 | I12: =I10+I11 -> 7847
A13: Cost of sales | G13: Cost of materials | H13: =B19 -> -5252 | I13: =C19 -> -3693
A14: Gross profit on sales | B14: 10456 | C14: 7847 | G14: Other operating expenses | H14: -1100 | I14: -870
A15: Selling and distribution costs | G15: Other operating income | H15: 110 | I15: 98
A16: Research and development expenses | G16: Added Value | H16: =H12+H13+H14+H15 -> 4214 | I16: =I12+I13+I14+I15 -> 3382
A17: General administrative expenses | G17: Personnel expenses | H17: =B21 -> -2314 | I17: =C21 -> -1844
A18: Other operating income | B18: 273 | C18: 178 | G18: EBITDA | H18: =H16+H17 -> 1900 | I18: =I16+I17 -> 1538
A19: Cost of materials | B19: -5252 | C19: -3693 | G19: Amortization, depreciation (excl impairment) | H19: -389 | I19: =C22 -> -284
G20: Restructuring costs removed | H20: 7 | I20: 2
A21: Personnel expenses | B21: -2314 | C21: -1844 | G21: Core Operating Income | H21: =H18+H19+H20 -> 1518 | I21: =I18+I19+I20 -> 1256
A22: Amortization, depreciation and impairment | B22: -406 | C22: -284 | G22: Results from equity-method investments (excluding AIM) | H22: 1 | I22: =C24 -> -33
A23: Other operating expenses | B23: -1112 | C23: -891 | G23: Other net financial income | H23: -22 | I23: =C25 -> -9
A24: Result from investments accounted for using the equity method | B24: 47 | C24: -33 | G24: Non-core Operating Income | H24: =H23+H22 -> -21 | I24: =I23+I22 -> -42
A25: Other net financial income | B25: -7 | C25: -9 | G25: Operating Income (EBIT) | H25: =H24+H21 -> 1497 | I25: =I24+I21 -> 1214
A26: Earnings before interest and taxes (EBIT) | B26: 1684 | C26: 1270 | G26: Net interest income | H26: =B28 -> 4 | I26: =C28 -> 14
A27: Net financial income | B27: -112 | C27: -102 | G27: Net interest expenses | H27: =B29 -> -116 | I27: =C29 -> -116
A28: Net interest income | B28: 4 | C28: 14 | G28: Net financial expenses | H28: =H26+H27 -> -112 | I28: =I26+I27 -> -102
A29: Net interest income / expenses | B29: -116 | C29: -116 | G29: Income before unusual items & taxes | H29: =H28+H24+H21 -> 1385 | I29: =I28+I24+I21 -> 1112
A30: Net investment income and other net financial income | G30: Refunds (mainly insurance for 2025 production losses) | H30: 118 | I30: 21
A31: Other net financial income | G31: Reversal of provisions | H31: 44 | I31: 55
A32: Financial expenses | G32: Disposals of non-current assets, net | H32: -8 | I32: -19
A33: Financial result | B33: -112 | C33: -102 | G33: Impairment / write-back | H33: -17 | I33: 2
A34: Earnings before taxes (EBT) | B34: 1572 | C34: 1168 | G34: Gain on sale of AIM stake | H34: 46 | I34: 0
A35: Income taxes | B35: -396 | C35: -328 | G35: Revaluation of previously held blackned stake | H35: 15 | I35: 0
A36: Earnings from continuing operations | B36: 1176 | C36: 840 | G36: NVL Acquisition cost | H36: -3 | I36: 0
A37: Earnings from discontinued operations | B37: -341 | C37: -32 | G37: Restructuring costs | H37: -7 | I37: -2
A38: Earnings after taxes | B38: 835 | C38: 808 | G38: Prior-period income taxes | H38: -11 | I38: 1
A39: Earnings after taxes attributable to minority interests | B39: -139 | C39: -91 | G39: Effect of changes in taxes | H39: 10 | I39: 0
A40: Earnings after taxes attributable to Rheinmetall AG shareholders | B40: 696 | C40: 717 | G40: Discontinued operations | H40: -315 | I40: -17
G41: Other comprehensive income | H41: -11 | I41: 238
G42: Unusual items | H42: =H41+H40+H38+H37+H36+H35+H34+H33+H32+H31+H30+H39 -> -139 | I42: =I41+I40+I38+I37+I36+I35+I34+I33+I32+I31+I30+I39 -> 279
G43: Income before taxes | H43: =H42+H29 -> 1246 | I43: =I42+I29 -> 1391
G44: Income taxes (continuing operations) | H44: =B35-H38-H39 -> -395 | I44: =C35-I38-I39 -> -329
...

Sheet Balance Sheet 
A1: Rheinmetall AG (RHM-DE)
A2: €1010.60
A5: Rheinmetall AG Statement of Financial Position | G5: Rheinmetall AG Reclassified Statement of Financial Position (Managerial)
A6: RHM-DE 5334588 Xetra Common stock | G6: RHM-DE 5334588 Xetra Common stock
B8: 31 DEC '25 | C8: 31 DEC '24 | H8: 31 DEC '25 | I8: 31 DEC '24
A9: Total assets | B9: =B10+B23 -> 16772 | C9: 14344 | G9: Inventories | H9: =B24 -> 4721 | I9: =C24 -> 3989
A10: Non-current assets | B10: 5871 | C10: 6112 | G10: Contract assets | H10: =B27 -> 957 | I10: =C27 -> 692
A11: Intangible assets | B11: 2598 | C11: 2802 | G11: Trade receivables | H11: =B28 -> 1907 | I11: =C28 -> 1959
A12: Goodwill | B12: 1354 | C12: 1426 | G12: Contract acquisition costs and contract costs | H12: 198 | I12: 183
A13: Other intangible assets | B13: 1244 | C13: 1376 | G13: Prepaid expenses and other non-financial assets | H13: 137 | I13: 160
A14: Right-of-use assets | B14: 338 | C14: 334 | G14: Derivative assets (hedges of operating risks) | H14: 80 | I14: 41
A15: Property, plant and equipment | B15: 1962 | C15: 1853 | G15: Current operating assets | H15: =SUM(H9:H14) -> 8000 | I15: =SUM(I9:I14) -> 7024
A16: Financial assets | G16: Contract liabilities | H16: =B62 -> 5642 | I16: =C62 -> 3866
A17: Investment property | B17: 2 | C17: 20 | G17: Trade liabilities | H17: =B63 -> 1186 | I17: =C63 -> 1151
A18: Investments accounted for using the equity method | B18: 213 | C18: 346 | G18: Other current provisions | H18: =B56 -> 891 | I18: =C56 -> 807
A19: Other non-current assets | B19: 592 | C19: 585 | G19: Pension provisions net of plan surplus | H19: -11 | I19: 252
A20: Other non-current financial assets | G20: Other non-current provisions | H20: =B47 -> 280 | I20: =C47 -> 285
A21: Other non-current assets excluding other non-current financial assets | G21: Social security and other non-financial liabilities | H21: 100 | I21: 144
A22: Deferred taxes | B22: 165 | C22: 172 | G22: Derivative liabilities (hedges of operating risks) | H22: 20 | I22: 22
A23: Current assets | B23: 10901 | C23: 8231 | G23: Operating liabilities | H23: =SUM(H16:H22) -> 8108 | I23: =SUM(I16:I22) -> 6527
A24: Inventories, net | B24: 4721 | C24: 3989 | G24: NOWC | H24: =H15-H23 -> -108 | I24: =I15-I23 -> 497
A25: Inventories | G25: Goodwill | H25: =B12 -> 1354 | I25: =C12 -> 1426
A26: Prepayments received | G26: Other intangible assets | H26: =B13 -> 1244 | I26: =C13 -> 1376
A27: Contract assets | B27: 957 | C27: 692 | G27: Right-of-use assets | H27: =B14 -> 338 | I27: =C14 -> 334
A28: Trade receivables | B28: 1907 | C28: 1959 | G28: Property, plant and equipment | H28: =B15 -> 1962 | I28: =C15 -> 1853
A29: Other current assets | B29: 384 | C29: 350 | G29: Investment property | H29: =B17 -> 2 | I29: =C17 -> 20
A30: Income tax receivables | B30: 11 | C30: 57 | G30: Non-current operating assets | H30: =H25+H26+H27+H28+H29 -> 4900 | I30: =I25+I26+I27+I28+I29 -> 5009
G31: Core Operating Invested Capital | H31: =H30+H15 -> 12900 | I31: =I30+I15 -> 12033
A32: Other financial assets | G32: Net operating assets | H32: =H30+H24 -> 4792 | I32: =I30+I24 -> 5506
A33: Liquid financial assets | G33: Investments accounted for using the equity method | H33: =B18 -> 213 | I33: =C18 -> 346
A34: Other current receivables and assets | G34: Held for sale, net | H34: =B38-B68 -> 562 | I34: =C38-C68 -> 0
A35: Securities held for trade | G35: Non-current financial assets (bonds, other; excl. derivatives) | H35: 45 | I35: 81
A36: Current tax assets | G36: Non-operating assets | H36: =SUM(H33:H35) -> 820 | I36: =SUM(I33:I35) -> 427
A37: Cash and cash equivalents | B37: 1650 | C37: 1184 | G37: Total Invested Capital | H37: =H36+H31 -> 13720 | I37: =I36+I31 -> 12460
A38: Assets held for sale | B38: 1270 | C38: 0 | G38: Net invested capital | H38: =H32+H36 -> 5612 | I38: =I32+I36 -> 5933
A39: Total equity and liabilities | B39: 16772 | C39: 14344 | G39: Financial debts (incl. lease liabilities 306/327) | H39: 1281 | I39: 2423
A40: Equity | B40: 5614 | C40: 4465 | G40: Other financial liabilities (excl. derivatives) | H40: 23 | I40: 77
A41: Share capital | B41: 118 | C41: 112 | G41: Cash and cash equivalents | H41: =-B37 -> -1650 | I41: =-C37 -> -1184
A42: Capital reserves | B42: 1394 | C42: 696 | G42: Current financial assets (excl. derivatives) | H42: -41 | I42: -81
A43: Retained earnings | B43: 3503 | C43: 3247 | G43: Net financial position | H43: =SUM(H39:H42) -> -387 | I43: =SUM(I39:I42) -> 1235
...

Sheet ROE + Decomposition
J1: Balance Sheet | Q1: Income statement | R1: 31 DEC '25 | S1: 31 DEC '24
A2: DuPont Decomposition | B2: 2025 | C2: 2024 | K2: 31 DEC '25 | L2: 31 DEC '24 | Q2: Sales | R2: 9935 | S2: 7715
A3: Net income | B3: ='Income Statement'!B38 -> 835 | C3: ='Income Statement'!C38 -> 808 | J3: Inventories | K3: 4721 | L3: 3989 | Q3: Changes in inventories and work performed by the enterprise and capitalised | R3: 521 | S3: 132
A4: EBT | B4: ='Income Statement'!B34 -> 1572 | C4: ='Income Statement'!C34 -> 1168 | J4: Contract assets | K4: 957 | L4: 692 | Q4: Value of Production | R4: 10456 | S4: 7847
B5: =B3/B4 -> 0.53117048 | C5: =C3/C4 -> 0.69178082 | J5: Trade receivables | K5: 1907 | L5: 1959 | Q5: Cost of materials | R5: -5252 | S5: -3693
J6: Contract acquisition costs and contract costs | K6: 198 | L6: 183 | Q6: Other operating expenses | R6: -1100 | S6: -870
A7: EBT | B7: =B4 -> 1572 | C7: =C4 -> 1168 | J7: Prepaid expenses and other non-financial assets | K7: 137 | L7: 160 | Q7: Other operating income | R7: 110 | S7: 98
A8: EBIT | B8: ='Income Statement'!B26 -> 1684 | C8: ='Income Statement'!C26 -> 1270 | J8: Derivative assets (hedges of operating risks) | K8: 80 | L8: 41 | Q8: Added Value | R8: 4214 | S8: 3382
B9: =B7/B8 -> 0.93349169 | C9: =C7/C8 -> 0.91968504 | J9: Current operating assets | K9: 8000 | L9: 7024 | Q9: Personnel expenses | R9: -2314 | S9: -1844
J10: Contract liabilities | K10: 5642 | L10: 3866 | Q10: EBITDA | R10: 1900 | S10: 1538
A11: EBIT | B11: =B8 -> 1684 | C11: =C8 -> 1270 | J11: Trade liabilities | K11: 1186 | L11: 1151 | Q11: Amortization, depreciation (excl impairment) | R11: -389 | S11: -284
A12: Sales | B12: ='Income Statement'!H10 -> 9935 | C12: ='Income Statement'!I10 -> 7715 | J12: Other current provisions | K12: 891 | L12: 807 | Q12: Restructuring costs removed | R12: 7 | S12: 2
B13: =B11/B12 -> 0.16950176 | C13: =C11/C12 -> 0.16461439 | J13: Pension provisions net of plan surplus | K13: -11 | L13: 252 | Q13: Core Operating Income | R13: 1518 | S13: 1256
A14: Sales | B14: ='Income Statement'!H10 -> 9935 | C14: ='Income Statement'!I10 -> 7715 | J14: Other non-current provisions | K14: 280 | L14: 285 | Q14: Results from equity-method investments (excluding AIM) | R14: 1 | S14: -33
A15: Total Assets | B15: =K47 -> 16770 | C15: ='Balance Sheet '!C9 -> 14344 | J15: Social security and other non-financial liabilities | K15: 100 | L15: 144 | Q15: Other net financial income | R15: -22 | S15: -9
B16: =B14/B15 -> 0.59242695 | C16: =C14/C15 -> 0.53785555 | J16: Derivative liabilities (hedges of operating risks) | K16: 20 | L16: 22 | Q16: Non-core Operating Income | R16: -21 | S16: -42
A17: Total Assets | B17: =K47 -> 16770 | C17: =C15 -> 14344 | J17: Operating liabilities | K17: 8108 | L17: 6527 | Q17: Operating Income (EBIT) | R17: 1497 | S17: 1212
A18: Equity | B18: =K42 -> 5614 | C18: =L42 -> 4465 | J18: NOWC | K18: -108 | L18: 497 | Q18: Net interest income | R18: 4 | S18: 14
B19: =B17/B18 -> 2.9871749 | C19: =C17/C18 -> 3.212542 | J19: Goodwill | K19: 1354 | L19: 1426 | Q19: Net interest expenses | R19: -116 | S19: -116
A21: DuPont ROE | B21: =B5*B9*B13*B16*B19 -> 0.1487353 | C21: =C5*C9*C13*C16*C19 -> 0.18096305 | J21: Other intangible assets | K21: 1244 | L21: 1376 | Q21: Net financial expenses | R21: -112 | S21: -102
J22: Right-of-use assets | K22: 338 | L22: 334 | Q22: Income before unusual items & taxes | R22: 1385 | S22: 1112
A23: Modigliani Miller Decomposition (adjusted)
A24: Operating Income | B24: ='Income Statement'!H21 -> 1518 | C24: ='Income Statement'!I21 -> 1256 | J24: Property, plant and equipment | K24: 1962 | L24: 1853 | Q24: Refunds (mainly insurance for 2025 production losses) | R24: 118 | S24: 21
A25: Net Operating invested capital | B25: ='Balance Sheet '!H15-'Balance Sheet '!H23+'Balance Sheet '!H30-'Balance Sheet '!H46 -> 4407 | C25: ='Balance Sheet '!I15-'Balance Sheet '!I23+'Balance Sheet '!I30-'Balance Sheet '!I46 -> 5273 | J25: Investment property | K25: 2 | L25: 20 | Q25: Reversal of provisions | R25: 44 | S25: 55
A26: Ratio 1 | B26: =B24/B25 -> 0.34445201 | C26: =C24/C25 -> 0.23819458 | J26: Non-current operating assets | K26: 4900 | L26: 5009 | Q26: Disposals of non-current assets, net | R26: -8 | S26: -19
J27: Net operating invested capital | K27: 4792 | L27: 5506 | Q27: Impairment / write-back | R27: -17 | S27: 2
A28: Net Financial Revenue/Net Financial Expenses | B28: ='Income Statement'!H24+'Income Statement'!H28 -> -133 | C28: =-('Income Statement'!I24+'Income Statement'!I28) -> 144 | J28: Investments accounted for using the equity method | K28: 213 | L28: 346 | Q28: Gain on sale of AIM stake | R28: 46 | S28: 0
A29: Net Financial Assets/ Net Financial Obligations | B29: =K57 -> 1207 | C29: =L57 -> 808 | J29: Held for sale, net | K29: 562 | L29: 0 | Q29: Revaluation of previously held blackned stake | R29: 15 | S29: 0
A30: Ratio 2 | B30: =B28/B29 -> -0.11019056 | C30: =C28/C29 -> 0.17821782
J31: Non-current financial assers (bonds, other; excl. derivatives) | K31: 45 | L31: 81 | Q31: NVL Acquisition cost | R31: -3 | S31: 0
A32: Net Financial Assets/ Net Financial Obligations | B32: =K57 -> 1207 | C32: =L57 -> 808 | J32: Non-operating assets | K32: 820 | L32: 427 | Q32: Restructuring costs | R32: -7 | S32: -2
A33: Net Equity | B33: =K42 -> 5614 | C33: =L42 -> 4465 | J33: Net invested capital | K33: 5612 | L33: 5933 | Q33: Prior-period income taxes | R33: -11 | S33: -1
A34: Ratio 3 | B34: =B32/B33 -> 0.21499822 | C34: =C32/C33 -> 0.18096305 | J34: Financial debts (incl. lease liabilities 306/327) | K34: 1281 | L34: 2423 | Q34: Effect of changes in taxes | R34: 10 | S34: 0
J35: Other financial liabilities (excl. derivatives) | K35: 23 | L35: 77 | Q35: Discontinued operations | R35: -315 | S35: -17
A36: Compr Income | B36: ='Income Statement'!H49 -> 786 | C36: ='Income Statement'!I49 -> 999 | J36: Cash and cash equivalents | K36: -1650 | L36: -1184 | Q36: Other comprehensive income | R36: -11 | S36: 238
A37: Income Before Unus and tax | B37: ='Income Statement'!H29 -> 1385 | C37: ='Income Statement'!I29 -> 1112 | J37: Current financial assets (excl. derivatives) | K37: -41 | L37: -81 | Q37: Unusual items | R37: -139 | S37: 279
A38: Ratio 4 | B38: =B36/B37 -> 0.56750903 | C38: =C36/C37 -> 0.89838129 | J38: Net financial position | K38: -387 | L38: 1235 | Q38: Income before taxes | R38: 1246 | S38: 1387
A39: Modigliani Miller ROE | B39: =(B26-(B26-B30)*B34)*B38 -> 0.14000713 | C39: =(C26+(C26-C30)*C34)*C38 -> 0.2237402 | J39: Tax liabilities (deferred, income, other taxes) | K39: 747 | L39: 576 | Q39: Income taxes (continuing operations) | R39: -396 | S39: -328
J40: Tax assets (deferred, income, other taxes) | K40: -362 | L40: -343 | Q40: Income taxes (discontinued operations) | R40: -27 | S40: -14
A41: Penman Decomposition | J41: Net tax position | K41: 385 | L41: 233 | Q41: Taxes on other comprehensive income | R41: -38 | S41: -47
...

Sheet ROI + Decomposition
A2: GROSS | B2: 2025 | C2: 2024 | G2: Balance Sheet | N2: INCOME STATEMENT | O2: 31 DEC '25 | P2: 31 DEC '24
A3: Core operating income | B3: ='Income Statement'!H21 -> 1518 | C3: ='Income Statement'!I21 -> 1256 | H3: 31 DEC '25 | I3: 31 DEC '24 | N3: Sales | O3: 9935 | P3: 7715
A4: Core operating invested capital | B4: =('Balance Sheet '!H30)+'Balance Sheet '!H15 -> 12900 | C4: =('Balance Sheet '!I30)+'Balance Sheet '!I15 -> 12033 | G4: Inventories | H4: 4721 | I4: 3989 | N4: Changes in inventories and work performed by the enterprise and capitalised | O4: 521 | P4: 132
A5: Total invested capital | B5: ='Balance Sheet '!H15+'Balance Sheet '!H30+'Balance Sheet '!H36 -> 13720 | C5: ='Balance Sheet '!I15+'Balance Sheet '!I30+'Balance Sheet '!I36 -> 12460 | G5: Contract assets | H5: 957 | I5: 692 | N5: Value of Production | O5: 10456 | P5: 7847
A6: Non-core operating income | B6: ='Income Statement'!H24 -> -21 | C6: ='Income Statement'!I24 -> -42 | G6: Trade receivables | H6: 1907 | I6: 1959 | N6: Cost of materials | O6: -5252 | P6: -3693
A7: Non-core operating invested capital | B7: ='Balance Sheet '!H36 -> 820 | C7: ='Balance Sheet '!I36 -> 427 | G7: Contract acquisition costs and contract costs | H7: 198 | I7: 183 | N7: Other operating expenses | O7: -1100 | P7: -870
G8: Prepaid expenses and other non-financial assets | H8: 137 | I8: 160 | N8: Other operating income | O8: 110 | P8: 98
A9: ROI (Gross) | B9: =(B3/B4)*(B4/B5) + (B6/B7)*(B7/B5) -> 0.10911079 | C9: =(C3/C4)*(C4/C5) + (C6/C7)*(C7/C5) -> 0.097431782 | G9: Derivative assets (hedges of operating risks) | H9: 80 | I9: 41 | N9: Added Value | O9: 4214 | P9: 3382
G10: Current operating assets | H10: 8000 | I10: 7024 | N10: Personnel expenses | O10: -2314 | P10: -1844
A11: NET | B11: 2025 | C11: 2024 | G11: Contract liabilities | H11: 5642 | I11: 3866 | N11: EBITDA | O11: 1900 | P11: 1538
A12: Core operating income | B12: ='Income Statement'!H21 -> 1518 | C12: ='Income Statement'!I21 -> 1256 | G12: Trade liabilities | H12: 1186 | I12: 1151 | N12: Amortization, depreciation (excl impairment) | O12: -389 | P12: -284
A13: Core operating invested capital (net) | B13: ='Balance Sheet '!H32+'Balance Sheet '!H33+'Balance Sheet '!H34-'Balance Sheet '!H46 -> 5182 | C13: ='Balance Sheet '!I32 -> 5506 | G13: Other current provisions | H13: 891 | I13: 807 | N13: Restructuring costs removed | O13: 7 | P13: 2
A14: Net Invested Capital | B14: ='Balance Sheet '!H38 -> 5612 | C14: ='Balance Sheet '!I38 -> 5933 | G14: Pension provisions net of plan surplus | H14: -11 | I14: 252 | N14: Core Operating Income | O14: 1518 | P14: 1254
A15: Non-core operating income | B15: ='Income Statement'!H24 -> -21 | C15: ='Income Statement'!I24 -> -42 | G15: Other non-current provisions | H15: 280 | I15: 285 | N15: Results from equity-method investments (excluding AIM) | O15: 1 | P15: -33
A16: Non-core net invested capital | B16: ='Balance Sheet '!H36 -> 820 | C16: ='Balance Sheet '!I36 -> 427 | G16: Social security and other non-financial liabilities | H16: 100 | I16: 144 | N16: Other net financial income | O16: -22 | P16: -9
G17: Derivative liabilities (hedges of operating risks) | H17: 20 | I17: 22 | N17: Non-core Operating Income | O17: -21 | P17: -42
A18: ROI (NET) | B18: =(B12/B13)*(B13/B14) + (B15/B16)*(B16/B14) -> 0.26674982 | C18: =(C12/C13)*(C13/C14) + (C15/C16)*(C16/C14) -> 0.20461824 | G18: Operating liabilities | H18: 8108 | I18: 6527 | N18: Operating Income (EBIT) | O18: 1497 | P18: 1212
G19: NOWC | H19: -108 | I19: 497 | N19: Net interest income | O19: 4 | P19: 14
G20: Goodwill | H20: 1354 | I20: 1426 | N20: Net interest expenses | O20: -116 | P20: -116
G21: Other intangible assets | H21: 1244 | I21: 1376 | N21: Net financial expenses | O21: -112 | P21: -102
G22: Right-of-use assets | H22: 338 | I22: 334 | N22: Income before unusual items & taxes | O22: 1385 | P22: 1110
G23: Property, plant and equipment | H23: 1962 | I23: 1853 | N23: Refunds (mainly insurance for 2025 production losses) | O23: 118 | P23: 21
G24: Investment property | H24: 2 | I24: 20 | N24: Reversal of provisions | O24: 44 | P24: 55
G25: Non-current operating assets | H25: 4900 | I25: 5009 | N25: Disposals of non-current assets, net | O25: -8 | P25: -19
G26: Net operating invested capital | H26: 4792 | I26: 5506 | N26: Impairment / write-back | O26: -17 | P26: 2
G27: Investments accounted for using the equity method | H27: 213 | I27: 346 | N27: Gain on sale of AIM stake | O27: 46 | P27: 0
G28: Held for sale, net | H28: 562 | I28: 0 | N28: Revaluation of previously held blackned stake | O28: 15 | P28: 0
G29: Non-current financial assers (bonds, other; excl. derivatives) | H29: 45 | I29: 81 | N29: NVL Acquisition cost | O29: -3 | P29: 0
G30: Non-operating assets | H30: 820 | I30: 427 | N30: Restructuring costs | O30: -7 | P30: -2
... G41: Total financing | H41: 5612 | I41: 5933 | N41: Comprehensive income | O41: 785 | P41: 998
N42: of which non controlling interests | O42: 150 | P42: 98
N43: of which Rheinmetall AG shareholders | O43: 636 | P43: 901
